<?xml version="1.0" encoding="utf-8"?>
<robot name="happymimiGen2" xmlns:xacro="http://ros.org/wiki/xacro">
  <xacro:include filename="$(find happymimi_description)/urdf/body/body.urdf.xacro"/>
  <xacro:include filename="$(find realsense2_description)/urdf/_d435.urdf.xacro"/>
  <!-- <xacro:include filename="$(find realsense2_description)/urdf/_d435i.urdf.xacro"/> -->

  <link name="base_footprint"/>
  <xacro:body parent="base_footprint">
    <origin xyz="0 0 0"/>
  </xacro:body>

  <material name="orange">
    <color rgba="1.0 0.5 0.2 1" />
  </material>
  <material name="gray">
    <color rgba="0.25 0.25 0.25 1" />
  </material>

  <!-- spine -->
  <joint name="spine_joint" type="fixed">
    <parent link="base_link"/>
    <child  link="spine_link"/>
    <origin xyz="-0.03 0 0.165" rpy="0 0 0"/>
  </joint>
  <link name="spine_link">
    <visual>
      <origin xyz="0 0 0.361" rpy="0 0 0"/>
      <geometry>
        <box size="0.03 0.03 0.72"/>
      </geometry>
      <material name="gray" />
    </visual>
  </link>

  <!-- neck -->
  <joint name="m5_neck_joint" type="revolute">
  <!-- <joint name="neck_joint" type="fixed"> -->
    <parent link="spine_link" />
    <child  link="neck_link" />
    <origin xyz="0 0 0.722" rpy="0 0.38 0" />
    <axis xyz="0 1 0" />
    <limit lower="-1.5" upper="1.5" effort="1000" velocity="0.5" />
  </joint>
  <link name="neck_link">
    <visual>
      <origin xyz="0 0 0" rpy="0 0 0"/>
      <geometry>
        <!-- <cylinder length="0.03" radius="0.03" /> -->
        <box size="0.05 0.045 0.09 " />
      </geometry>
      <material name="gray" />
    </visual>
  </link>

  <!--  2d-lidar  -->
  <joint name="base_laser_link_joint" type="fixed">
    <parent link="base_footprint" />
    <child link="base_laser_link" />
    <origin xyz="0.1 0 0.105" rpy="3.14159 0.0 0.0"/>
  </joint>
  <link name="base_laser_link">
    <visual>
      <origin xyz="0 0 0" rpy="0 3.14 3.14"/>
      <geometry>
        <mesh filename="package://happymimi_description/meshes/stl/lrf.stl" />
        <!-- <cylinder length="0.09" radius="0.03" /> -->
      </geometry>
      <material name="orange" />
    </visual>
  </link>

  <!-- IMU -->
  <joint name="imu_joint" type="fixed">
    <parent link="base_link" />
    <child link="imu_link" />
    <origin xyz="-0.03 0.05 0.185" rpy="0.0 0.0 0.0"/>
  </joint>
  <link name="imu_link">
    <visual>
      <origin xyz="0 0 0" rpy="0 0 0"/>
      <geometry>
        <box size="0.03 0.03 0.004"/>
      </geometry>
      <material name="orange" />
    </visual>
  </link>


  <!--  realsense for RGB-D Camera -->
  <xacro:sensor_d435 parent="neck_link">
    <origin xyz="0.07 0 0.15"/>
  </xacro:sensor_d435>

  <!-- <xacro:sensor_d435i parent="base_link" use_nominal_extrinsics="false"> -->
  <!-- <xacro:sensor_d435i parent="neck_link" use_nominal_extrinsics="false"> -->
    <!-- <origin xyz="0 0 0.90"/> -->
    <!-- <origin xyz="0.07 0 0.15"/> -->
  <!-- </xacro:sensor_d435i> -->

  <!--  respeaker  -->
  <joint name="respeaker_link_joint" type="fixed">
    <parent link="neck_link" />
    <child link="respeaker_link" />
    <origin xyz="0 0 0.2" rpy="0 0 0"/>
  </joint>
  <link name="respeaker_link">
    <visual>
      <origin xyz="0 0 0" rpy="0 0 0"/>
      <geometry>
        <cylinder length="0.0015" radius="0.035" />
      </geometry>
      <material name="orange" />
    </visual>
  </link>

</robot>
