<?xml version="1.0" encoding="utf-8"?>
<!-- =================================================================================== -->
<!-- |    This document was autogenerated by xacro from happymimi.urdf.xacro           | -->
<!-- |    EDITING THIS FILE BY HAND IS NOT RECOMMENDED                                 | -->
<!-- =================================================================================== -->
<robot name="happymimiGen2">
  <link name="base_footprint"/>
  <joint name="base_joint" type="fixed">
    <origin xyz="0 0 0"/>
    <parent link="base_footprint"/>
    <child link="base_link"/>
  </joint>
  <link name="base_link">
    <visual>
      <origin xyz="-0.028241 -0.073553 0.01"/>
      <geometry>
        <mesh filename="package://happymimi_description/meshes/dae/megarover.dae"/>
      </geometry>
    </visual>
  </link>
  <material name="orange">
    <color rgba="1.0 0.5 0.2 1"/>
  </material>
  <material name="gray">
    <color rgba="0.25 0.25 0.25 1"/>
  </material>
  <!-- spine -->
  <joint name="spine_joint" type="fixed">
    <parent link="base_link"/>
    <child link="spine_link"/>
    <origin rpy="0 0 0" xyz="-0.03 0 0.165"/>
  </joint>
  <link name="spine_link">
    <visual>
      <origin rpy="0 0 0" xyz="0 0 0.361"/>
      <geometry>
        <cylinder length="0.722" radius="0.02"/>
      </geometry>
      <material name="gray"/>
    </visual>
  </link>
  <!-- neck -->
  <joint name="neck_joint" type="revolute">
    <!-- <joint name="neck_joint" type="fixed"> -->
    <parent link="spine_link"/>
    <child link="neck_link"/>
    <origin rpy="0 0 0" xyz="0 0 0.722"/>
    <axis xyz="0 1 0"/>
    <limit effort="1000" lower="-1.5" upper="1.5" velocity="0.5"/>
  </joint>
  <link name="neck_link">
    <visual>
      <origin rpy="0 0 0" xyz="0 0 0"/>
      <geometry>
        <cylinder length="0.03" radius="0.03"/>
      </geometry>
      <material name="gray"/>
    </visual>
  </link>
  <!--  lidar  -->
  <joint name="base_laser_link_joint" type="fixed">
    <parent link="base_footprint"/>
    <child link="base_laser_link"/>
    <origin rpy="3.14159 0.0 0.0" xyz="0.1 0 0.105"/>
  </joint>
  <link name="base_laser_link">
    <visual>
      <origin rpy="0 3.14 3.14" xyz="0 0 0"/>
      <geometry>
        <mesh filename="package://happymimi_description/meshes/stl/lrf.stl"/>
        <!-- <cylinder length="0.09" radius="0.03" /> -->
      </geometry>
      <material name="orange"/>
    </visual>
  </link>
  <material name="camera_aluminum">
    <color rgba="0.5 0.5 0.5 1"/>
  </material>
  <!-- camera body, with origin at bottom screw mount -->
  <joint name="camera_joint" type="fixed">
    <origin xyz="0.07 0 0.15"/>
    <parent link="neck_link"/>
    <child link="camera_bottom_screw_frame"/>
  </joint>
  <link name="camera_bottom_screw_frame"/>
  <joint name="camera_link_joint" type="fixed">
    <origin rpy="0 0 0" xyz="0 0.0175 0.0125"/>
    <parent link="camera_bottom_screw_frame"/>
    <child link="camera_link"/>
  </joint>
  <link name="camera_link">
    <visual>
      <origin rpy="1.57079632679 0 1.57079632679" xyz="0.0149 -0.0175 0"/>
      <geometry>
        <!-- <box size="${d435_cam_width} ${d435_cam_height} ${d435_cam_depth}"/> -->
        <mesh filename="package://realsense2_description/meshes/d435.dae"/>
        <!--<mesh filename="package://realsense2_description/meshes/d435/d435.dae" />-->
      </geometry>
      <material name="camera_aluminum"/>
    </visual>
    <collision>
      <origin rpy="0 0 0" xyz="0 -0.0175 0"/>
      <geometry>
        <box size="0.02505 0.09 0.025"/>
      </geometry>
    </collision>
    <inertial>
      <!-- The following are not reliable values, and should not be used for modeling -->
      <mass value="0.564"/>
      <origin xyz="0 0 0"/>
      <inertia ixx="0.003881243" ixy="0.0" ixz="0.0" iyy="0.000498940" iyz="0.0" izz="0.003879257"/>
    </inertial>
  </link>
  <!-- camera depth joints and links -->
  <joint name="camera_depth_joint" type="fixed">
    <origin rpy="0 0 0" xyz="0 0 0"/>
    <parent link="camera_link"/>
    <child link="camera_depth_frame"/>
  </joint>
  <link name="camera_depth_frame"/>
  <joint name="camera_depth_optical_joint" type="fixed">
    <origin rpy="-1.57079632679 0 -1.57079632679" xyz="0 0 0"/>
    <parent link="camera_depth_frame"/>
    <child link="camera_depth_optical_frame"/>
  </joint>
  <link name="camera_depth_optical_frame"/>
  <!-- camera left IR joints and links -->
  <joint name="camera_left_ir_joint" type="fixed">
    <origin rpy="0 0 0" xyz="0 0.0 0"/>
    <parent link="camera_depth_frame"/>
    <child link="camera_left_ir_frame"/>
  </joint>
  <link name="camera_left_ir_frame"/>
  <joint name="camera_left_ir_optical_joint" type="fixed">
    <origin rpy="-1.57079632679 0 -1.57079632679" xyz="0 0 0"/>
    <parent link="camera_left_ir_frame"/>
    <child link="camera_left_ir_optical_frame"/>
  </joint>
  <link name="camera_left_ir_optical_frame"/>
  <!-- camera right IR joints and links -->
  <joint name="camera_right_ir_joint" type="fixed">
    <origin rpy="0 0 0" xyz="0 -0.05 0"/>
    <parent link="camera_depth_frame"/>
    <child link="camera_right_ir_frame"/>
  </joint>
  <link name="camera_right_ir_frame"/>
  <joint name="camera_right_ir_optical_joint" type="fixed">
    <origin rpy="-1.57079632679 0 -1.57079632679" xyz="0 0 0"/>
    <parent link="camera_right_ir_frame"/>
    <child link="camera_right_ir_optical_frame"/>
  </joint>
  <link name="camera_right_ir_optical_frame"/>
  <!-- camera color joints and links -->
  <joint name="camera_color_joint" type="fixed">
    <origin rpy="0 0 0" xyz="0 0.015 0"/>
    <parent link="camera_depth_frame"/>
    <child link="camera_color_frame"/>
  </joint>
  <link name="camera_color_frame"/>
  <joint name="camera_color_optical_joint" type="fixed">
    <origin rpy="-1.57079632679 0 -1.57079632679" xyz="0 0 0"/>
    <parent link="camera_color_frame"/>
    <child link="camera_color_optical_frame"/>
  </joint>
  <link name="camera_color_optical_frame"/>
  <!-- Realsense Gazebo Plugin -->
  <!-- <xacro:gazebo_d435 camera_name="realsense" reference_link="$realsense_link" topics_ns="camera" depth_optical_frame="realsense_depth_optical_frame" color_optical_frame="realsense_color_optical_frame" infrared1_optical_frame="realsense_left_ir_optical_frame" infrared2_optical_frame="realsense_right_ir_optical_frame"/> -->
  <!--  respeaker  -->
  <joint name="respeaker_link_joint" type="fixed">
    <parent link="neck_link"/>
    <child link="respeaker_link"/>
    <origin rpy="0 0 0" xyz="0 0 0.2"/>
  </joint>
  <link name="respeaker_link">
    <visual>
      <origin rpy="0 0 0" xyz="0 0 0"/>
      <geometry>
        <cylinder length="0.0015" radius="0.035"/>
      </geometry>
      <material name="orange"/>
    </visual>
  </link>
</robot>

