<?xml version="1.0" encoding="utf-8"?>
<!-- =================================================================================== -->
<!-- |    This document was autogenerated by xacro from vhappymimi.urdf.xacro          | -->
<!-- |    EDITING THIS FILE BY HAND IS NOT RECOMMENDED                                 | -->
<!-- =================================================================================== -->
<robot name="vhappymimi">
  <!-- =============== Link & Joint =============== -->
  <!-- Base -->
  <link name="base_footprint"/>
  <joint name="base_link_joint" type="fixed">
    <origin xyz="0 0 0"/>
    <parent link="base_footprint"/>
    <child link="base_link"/>
  </joint>
  <link name="base_link">
    <visual>
      <geometry>
        <mesh filename="package://happymimi_description/meshes/dae/vmega_body.dae"/>
      </geometry>
    </visual>
    <collision>
      <geometry>
        <mesh filename="package://happymimi_description/meshes/stl/vmega_body.stl"/>
      </geometry>
    </collision>
    <inertial>
      <origin xyz="-0.061 0 -0.002"/>
      <mass value="13.754"/>
      <inertia ixx="0.110655982" ixy="0" ixz="0" iyy="0.20062619" iyz="0" izz="0.269504336"/>
    </inertial>
  </link>
  <joint name="right_wheel_joint" type="continuous">
    <origin xyz="0 -0.14199 0.074742"/>
    <parent link="base_link"/>
    <child link="right_wheel_link"/>
    <axis xyz="0 1 0"/>
  </joint>
  <link name="right_wheel_link">
    <visual>
      <geometry>
        <mesh filename="package://happymimi_description/meshes/dae/vmega_wheel.dae"/>
      </geometry>
    </visual>
    <collision>
      <origin rpy="-1.57079637 0 0" xyz="0 0 0"/>
      <geometry>
        <cylinder length="0.03" radius="0.076"/>
      </geometry>
    </collision>
    <inertial>
      <origin rpy="-1.57079637 0 0" xyz="0 0 0"/>
      <mass value="0.823"/>
      <inertia ixx="0.001250137" ixy="0" ixz="0" iyy="0.001250137" iyz="0" izz="0.002376824"/>
    </inertial>
  </link>
  <joint name="left_wheel_joint" type="continuous">
    <origin rpy="0 0 3.14159274" xyz="0 0.14199 0.074742"/>
    <parent link="base_link"/>
    <child link="left_wheel_link"/>
    <axis xyz="0 -1 0"/>
  </joint>
  <link name="left_wheel_link">
    <visual>
      <geometry>
        <mesh filename="package://happymimi_description/meshes/dae/vmega_wheel.dae"/>
      </geometry>
    </visual>
    <collision>
      <origin rpy="-1.57079637 0 0" xyz="0 0 0"/>
      <geometry>
        <cylinder length="0.03" radius="0.076"/>
      </geometry>
    </collision>
    <inertial>
      <origin rpy="-1.57079637 0 0" xyz="0 0 0"/>
      <mass value="0.823"/>
      <inertia ixx="0.001250137" ixy="0" ixz="0" iyy="0.001250137" iyz="0" izz="0.002376824"/>
    </inertial>
  </link>
  <joint name="front_lrf_joint" type="fixed">
    <origin xyz="0.099 0 0.1015"/>
    <parent link="base_link"/>
    <child link="front_lrf_link"/>
  </joint>
  <link name="front_lrf_link">
    <visual>
      <geometry>
        <mesh filename="package://happymimi_description/meshes/dae/lrf.dae"/>
      </geometry>
    </visual>
    <collision>
      <geometry>
        <mesh filename="package://happymimi_description/meshes/stl/lrf.stl"/>
      </geometry>
    </collision>
    <inertial>
      <origin xyz="0 0 0"/>
      <mass value="0.218"/>
      <inertia ixx="9.08333333333e-05" ixy="0" ixz="0" iyy="0.000134433333333" iyz="0" izz="0.000134433333333"/>
    </inertial>
  </link>
  <!-- Front LRF Upper-->
  <!-- <xacro:lrf_v0 prefix="front" parent="base_link">
  	<origin xyz="0.099 0 0.2155"  rpy="${M_PI} 0 0" />
  </xacro:lrf_v0> -->
  <!-- Rear LRF -->
  <!-- xacro:lrf_v0 prefix="rear" parent="base_link">
  	<origin xyz="-0.289 0 0.1015"  rpy="0 0 ${M_PI}" />
  </xacro:lrf_v0 -->
  <!-- <link name="lrf_link"/> -->
  <!-- <joint name="lrf_link_joint" type="fixed"> -->
  <!--   <parent link="base_footprint"/> -->
  <!--   <child link="lrf_link"/> -->
  <!--   <origin xyz="0.099 0 0.1015"/> -->
  <!-- </joint> -->
  <!-- Camera -->
  <!-- <link name="camera_link"/> -->
  <!-- <xacro:camera_v0 prefix="realsense" parent="base_link"> -->
  <!--   <origin xyz="0 0 0.7"/> -->
  <!-- </xacro:camera_v0> -->
  <!-- <xacro:include filename="$(find happymimi_description)/urdf/camera/d435.urdf.xacro" /> -->
  <!-- <xacro:sensor_d435 parent="base_link"> -->
  <!--   <origin xyz="0 0 0.7"/> -->
  <!-- </xacro:sensor_d435> -->
  <material name="camera_aluminum">
    <color rgba="0.5 0.5 0.5 1"/>
  </material>
  <!-- camera body, with origin at bottom screw mount -->
  <joint name="camera_joint" type="fixed">
    <origin xyz="0 0 0.7"/>
    <parent link="base_link"/>
    <child link="camera_bottom_screw_frame"/>
  </joint>
  <link name="camera_bottom_screw_frame"/>
  <joint name="camera_link_joint" type="fixed">
    <origin rpy="0 0 0" xyz="0 0.0175 0.0125"/>
    <parent link="camera_bottom_screw_frame"/>
    <child link="camera_link"/>
  </joint>
  <link name="camera_link">
    <visual>
      <origin rpy="1.57079632679 0 1.57079632679" xyz="0.0149 -0.0175 0"/>
      <geometry>
        <!-- <box size="${d435_cam_width} ${d435_cam_height} ${d435_cam_depth}"/> -->
        <mesh filename="package://realsense2_description/meshes/d435.dae"/>
        <!--<mesh filename="package://realsense2_description/meshes/d435/d435.dae" />-->
      </geometry>
      <material name="camera_aluminum"/>
    </visual>
    <collision>
      <origin rpy="0 0 0" xyz="0 -0.0175 0"/>
      <geometry>
        <box size="0.02505 0.09 0.025"/>
      </geometry>
    </collision>
    <inertial>
      <!-- The following are not reliable values, and should not be used for modeling -->
      <mass value="0.564"/>
      <origin xyz="0 0 0"/>
      <inertia ixx="0.003881243" ixy="0.0" ixz="0.0" iyy="0.000498940" iyz="0.0" izz="0.003879257"/>
    </inertial>
  </link>
  <!-- camera depth joints and links -->
  <joint name="camera_depth_joint" type="fixed">
    <origin rpy="0 0 0" xyz="0 0 0"/>
    <parent link="camera_link"/>
    <child link="camera_depth_frame"/>
  </joint>
  <link name="camera_depth_frame"/>
  <joint name="camera_depth_optical_joint" type="fixed">
    <origin rpy="-1.57079632679 0 -1.57079632679" xyz="0 0 0"/>
    <parent link="camera_depth_frame"/>
    <child link="camera_depth_optical_frame"/>
  </joint>
  <link name="camera_depth_optical_frame"/>
  <!-- camera left IR joints and links -->
  <joint name="camera_left_ir_joint" type="fixed">
    <origin rpy="0 0 0" xyz="0 0.0 0"/>
    <parent link="camera_depth_frame"/>
    <child link="camera_left_ir_frame"/>
  </joint>
  <link name="camera_left_ir_frame"/>
  <joint name="camera_left_ir_optical_joint" type="fixed">
    <origin rpy="-1.57079632679 0 -1.57079632679" xyz="0 0 0"/>
    <parent link="camera_left_ir_frame"/>
    <child link="camera_left_ir_optical_frame"/>
  </joint>
  <link name="camera_left_ir_optical_frame"/>
  <!-- camera right IR joints and links -->
  <joint name="camera_right_ir_joint" type="fixed">
    <origin rpy="0 0 0" xyz="0 -0.05 0"/>
    <parent link="camera_depth_frame"/>
    <child link="camera_right_ir_frame"/>
  </joint>
  <link name="camera_right_ir_frame"/>
  <joint name="camera_right_ir_optical_joint" type="fixed">
    <origin rpy="-1.57079632679 0 -1.57079632679" xyz="0 0 0"/>
    <parent link="camera_right_ir_frame"/>
    <child link="camera_right_ir_optical_frame"/>
  </joint>
  <link name="camera_right_ir_optical_frame"/>
  <!-- camera color joints and links -->
  <joint name="camera_color_joint" type="fixed">
    <origin rpy="0 0 0" xyz="0 0.015 0"/>
    <parent link="camera_depth_frame"/>
    <child link="camera_color_frame"/>
  </joint>
  <link name="camera_color_frame"/>
  <joint name="camera_color_optical_joint" type="fixed">
    <origin rpy="-1.57079632679 0 -1.57079632679" xyz="0 0 0"/>
    <parent link="camera_color_frame"/>
    <child link="camera_color_optical_frame"/>
  </joint>
  <link name="camera_color_optical_frame"/>
  <gazebo reference="$realsense_link">
    <self_collide>0</self_collide>
    <enable_wind>0</enable_wind>
    <kinematic>0</kinematic>
    <gravity>1</gravity>
    <!--<mu>1</mu>-->
    <mu2>1</mu2>
    <fdir1>0 0 0</fdir1>
    <!--<slip1>0</slip1>
      <slip2>0</slip2>-->
    <kp>1e+13</kp>
    <kd>1</kd>
    <!--<max_vel>0.01</max_vel>
      <min_depth>0</min_depth>-->
    <sensor name="realsensecolor" type="camera">
      <camera name="realsense">
        <horizontal_fov>1.21125850088</horizontal_fov>
        <image>
          <width>1920</width>
          <height>1080</height>
          <format>RGB_INT8</format>
        </image>
        <clip>
          <near>0.1</near>
          <far>100</far>
        </clip>
        <noise>
          <type>gaussian</type>
          <mean>0.0</mean>
          <stddev>0.007</stddev>
        </noise>
      </camera>
      <always_on>1</always_on>
      <update_rate>30</update_rate>
      <visualize>1</visualize>
    </sensor>
    <sensor name="realsenseired1" type="camera">
      <camera name="realsense">
        <horizontal_fov>1.4870205227</horizontal_fov>
        <image>
          <width>1280</width>
          <height>720</height>
          <format>L_INT8</format>
        </image>
        <clip>
          <near>0.1</near>
          <far>100</far>
        </clip>
        <noise>
          <type>gaussian</type>
          <mean>0.0</mean>
          <stddev>0.05</stddev>
        </noise>
      </camera>
      <always_on>1</always_on>
      <update_rate>90</update_rate>
      <visualize>0</visualize>
    </sensor>
    <sensor name="realsenseired2" type="camera">
      <camera name="realsense">
        <horizontal_fov>1.4870205227</horizontal_fov>
        <image>
          <width>1280</width>
          <height>720</height>
          <format>L_INT8</format>
        </image>
        <clip>
          <near>0.1</near>
          <far>100</far>
        </clip>
        <noise>
          <type>gaussian</type>
          <mean>0.0</mean>
          <stddev>0.05</stddev>
        </noise>
      </camera>
      <always_on>1</always_on>
      <update_rate>90</update_rate>
      <visualize>0</visualize>
    </sensor>
    <sensor name="realsensedepth" type="depth">
      <camera name="realsense">
        <horizontal_fov>1.4870205227</horizontal_fov>
        <image>
          <width>1280</width>
          <height>720</height>
        </image>
        <clip>
          <near>0.1</near>
          <far>100</far>
        </clip>
        <noise>
          <type>gaussian</type>
          <mean>0.0</mean>
          <stddev>0.100</stddev>
        </noise>
      </camera>
      <always_on>1</always_on>
      <update_rate>90</update_rate>
      <visualize>0</visualize>
    </sensor>
  </gazebo>
  <gazebo>
    <!-- <plugin name="${topics_ns}" filename="librealsense_gazebo_plugin.so"> -->
    <plugin filename="librealsense_gazebo_plugin.so" name="camera">
      <robotNamespace>/vhappymimi</robotNamespace>
      <prefix>realsense</prefix>
      <depthUpdateRate>60.0</depthUpdateRate>
      <colorUpdateRate>60.0</colorUpdateRate>
      <infraredUpdateRate>60.0</infraredUpdateRate>
      <depthTopicName>depth/image_raw</depthTopicName>
      <depthCameraInfoTopicName>depth/camera_info</depthCameraInfoTopicName>
      <colorTopicName>color/image_raw</colorTopicName>
      <colorCameraInfoTopicName>color/camera_info</colorCameraInfoTopicName>
      <infrared1TopicName>infra1/image_raw</infrared1TopicName>
      <infrared1CameraInfoTopicName>infra1/camera_info</infrared1CameraInfoTopicName>
      <infrared2TopicName>infra2/image_raw</infrared2TopicName>
      <infrared2CameraInfoTopicName>infra2/camera_info</infrared2CameraInfoTopicName>
      <colorOpticalframeName>realsense_color_optical_frame</colorOpticalframeName>
      <depthOpticalframeName>realsense_depth_optical_frame</depthOpticalframeName>
      <infrared1OpticalframeName>realsense_left_ir_optical_frame</infrared1OpticalframeName>
      <infrared2OpticalframeName>realsense_right_ir_optical_frame</infrared2OpticalframeName>
      <rangeMinDepth>0.2</rangeMinDepth>
      <rangeMaxDepth>10.0</rangeMaxDepth>
      <pointCloud>false</pointCloud>
      <pointCloudTopicName>depth/points</pointCloudTopicName>
      <pointCloudCutoff>0.5</pointCloudCutoff>
    </plugin>
  </gazebo>
  <!-- <joint name="camera_link_joint" type="fixed"> -->
  <!--   <parent link="base_footprint"/> -->
  <!--   <child link="camera_link"/> -->
  <!--   <origin xyz="0 0 0.7"/> -->
  <!-- </joint> -->
  <transmission name="right_wheel_trans">
    <type>transmission_interface/SimpleTransmission</type>
    <joint name="right_wheel_joint">
      <hardwareInterface>VelocityJointInterface</hardwareInterface>
    </joint>
    <actuator name="right_wheel_motor">
      <hardwareInterface>VelocityJointInterface</hardwareInterface>
      <mechanicalReduction>30</mechanicalReduction>
    </actuator>
  </transmission>
  <transmission name="left_wheel_trans">
    <type>transmission_interface/SimpleTransmission</type>
    <joint name="left_wheel_joint">
      <hardwareInterface>VelocityJointInterface</hardwareInterface>
    </joint>
    <actuator name="left_wheel_motor">
      <hardwareInterface>VelocityJointInterface</hardwareInterface>
      <mechanicalReduction>30</mechanicalReduction>
    </actuator>
  </transmission>
  <!-- =============== Gazebo =============== -->
  <gazebo>
    <plugin filename="libgazebo_ros_control.so" name="gazebo_ros_control">
      <robotNamespace>/vhappymimi</robotNamespace>
    </plugin>
  </gazebo>
  <gazebo reference="base_link">
    <selfCollide>false</selfCollide>
    <mu1 value="0.0"/>
    <mu2 value="0.0"/>
  </gazebo>
  <gazebo reference="right_wheel_link">
    <selfCollide>false</selfCollide>
    <mu1 value="1.0"/>
    <mu2 value="1.0"/>
  </gazebo>
  <gazebo reference="left_wheel_link">
    <selfCollide>false</selfCollide>
    <mu1 value="1.0"/>
    <mu2 value="1.0"/>
  </gazebo>
  <gazebo reference="front_lrf_link">
    <sensor name="front_lrf_sensor" type="ray">
      <pose>0 0 0 0 0 0</pose>
      <visualize>true</visualize>
      <update_rate>40</update_rate>
      <ray>
        <scan>
          <horizontal>
            <samples>1000</samples>
            <resolution>1</resolution>
            <min_angle>-1.57</min_angle>
            <max_angle>1.57</max_angle>
          </horizontal>
        </scan>
        <range>
          <min>0.06</min>
          <max>4.0</max>
          <resolution>0.001</resolution>
        </range>
        <noise>
          <type>gaussian</type>
          <mean>0.0</mean>
          <stddev>0.03</stddev>
        </noise>
      </ray>
      <plugin filename="libgazebo_ros_laser.so" name="gazebo_ros_front_lrf_controller">
        <!-- <topicName>${prefix}/scan</topicName> -->
        <topicName>/scan</topicName>
        <frameName>front_lrf_link</frameName>
      </plugin>
    </sensor>
  </gazebo>
  <!-- xacro:lrf_gazebo_v0 prefix="rear"
					   min_rad="-1.57" max_rad="1.57"
					   min_range="0.06" max_range="4.0"/ -->
</robot>

